<?xml version="1.0" encoding="utf-8"?>
<!-- =================================================================================== -->
<!-- |    This document was autogenerated by xacro from box_robots.xacro               | -->
<!-- |    EDITING THIS FILE BY HAND IS NOT RECOMMENDED                                 | -->
<!-- =================================================================================== -->
<robot name="box_robots" xmlns:xacro="http://ros.org/wiki/xacro">
  <material name="blue">
    <color rgba="0 0 1 1"/>
  </material>
  <material name="black">
    <color rgba="0 0 0 1"/>
  </material>
  <material name="white">
    <color rgba="1 1 1 1"/>
  </material>
  <material name="red">
    <color rgba="0.8 0 0 1"/>
  </material>
  <material name="green">
    <color rgba="0 1 0 1"/>
  </material>
  <material name="yellow">
    <color rgba="1 1 0 1"/>
  </material>
  <link name="world"/>
  <link name="box">
    <visual>
      <geometry>
        <box size="0.4 0.4 0.4"/>
      </geometry>
      <origin xyz="0 0 0.2"/>
      <material name="red"/>
    </visual>
    <collision>
      <geometry>
        <box size="0.4 0.4 0.4"/>
      </geometry>
    </collision>
    <inertial>
      <mass value="50.0"/>
      <inertia ixx="0.1" ixy="0.0" ixz="0.0" iyy="0.1" iyz="0.0" izz="0.1"/>
    </inertial>
  </link>
  <joint name="world_to_box" type="fixed">
    <origin rpy="0 0 0" xyz="0 0 0"/>
    <parent link="world"/>
    <child link="box"/>
  </joint>
  <link name="link1">
    <visual>
      <geometry>
        <cylinder length="0.1" radius="0.1"/>
      </geometry>
      <origin xyz="0 0 0.05"/>
      <material name="blue"/>
    </visual>
    <inertial>
      <mass value="1.0"/>
      <inertia ixx="0.1" ixy="0.0" ixz="0.0" iyy="0.1" iyz="0.0" izz="0.1"/>
    </inertial>
    <collision>
      <geometry>
        <cylinder length="0.1" radius="0.1"/>
      </geometry>
    </collision>
  </link>
  <joint name="box_link1" type="revolute">
    <axis xyz="0 0 1"/>
    <limit effort="100.0" lower="-3.1416" upper="3.1416" velocity="0.1"/>
    <parent link="box"/>
    <child link="link1"/>
    <origin rpy="0 0 0" xyz="0 0 0.4"/>
  </joint>
  <link name="link2">
    <visual>
      <geometry>
        <cylinder length="0.05" radius="0.05"/>
      </geometry>
      <origin rpy="0 1.57 0" xyz="0.025 0 0"/>
      <material name="black"/>
    </visual>
    <inertial>
      <mass value="0.5"/>
      <inertia ixx="0.1" ixy="0.0" ixz="0.0" iyy="0.1" iyz="0.0" izz="0.1"/>
    </inertial>
    <collision>
      <geometry>
        <cylinder length="0.05" radius="0.05"/>
      </geometry>
    </collision>
  </link>
  <joint name="link1_link2" type="fixed">
    <parent link="link1"/>
    <child link="link2"/>
    <origin rpy="0 0 0" xyz="0.1 0 0.05"/>
  </joint>
  <link name="link3">
    <visual>
      <geometry>
        <cylinder length="0.6" radius="0.05"/>
      </geometry>
      <origin rpy="0 0 0" xyz="0.05 0 0.3"/>
      <material name="yellow"/>
    </visual>
    <inertial>
      <mass value="5.0"/>
      <inertia ixx="0.1" ixy="0.0" ixz="0.0" iyy="0.1" iyz="0.0" izz="0.1"/>
    </inertial>
    <collision>
      <geometry>
        <cylinder length="0.6" radius="0.05"/>
      </geometry>
    </collision>
  </link>
  <joint name="link2_link3" type="revolute">
    <axis xyz="1 0 0"/>
    <limit effort="100.0" lower="-1.57" upper="1.57" velocity="0.5"/>
    <parent link="link2"/>
    <child link="link3"/>
    <origin rpy="0 0 0" xyz="0.05 0 0"/>
  </joint>
  <link name="link4">
    <visual>
      <geometry>
        <cylinder length="0.05" radius="0.05"/>
      </geometry>
      <origin rpy="0 1.57 0" xyz="0.025 0 0"/>
      <material name="black"/>
    </visual>
    <inertial>
      <mass value="0.5"/>
      <inertia ixx="0.1" ixy="0.0" ixz="0.0" iyy="0.1" iyz="0.0" izz="0.1"/>
    </inertial>
    <collision>
      <geometry>
        <cylinder length="0.05" radius="0.05"/>
      </geometry>
    </collision>
  </link>
  <joint name="link3_link4" type="fixed">
    <parent link="link3"/>
    <child link="link4"/>
    <origin rpy="0 0 0" xyz="0.1 0 0.6"/>
  </joint>
  <link name="link5">
    <visual>
      <geometry>
        <cylinder length="0.45" radius="0.05"/>
      </geometry>
      <origin rpy="0 0 0" xyz="0.05 0 0.225"/>
      <material name="yellow"/>
    </visual>
    <inertial>
      &gt;
						
      <mass value="1.0"/>
      <inertia ixx="0.1" ixy="0.0" ixz="0.0" iyy="0.1" iyz="0.0" izz="0.1"/>
    </inertial>
    <collision>
      <geometry>
        <cylinder length="0.45" radius="0.05"/>
      </geometry>
    </collision>
  </link>
  <joint name="link4_link5" type="revolute">
    <axis xyz="1 0 0"/>
    <limit effort="100.0" lower="-1.57" upper="1.57" velocity="0.5"/>
    <parent link="link4"/>
    <child link="link5"/>
    <origin rpy="0 0 0" xyz="0.05 0 0"/>
  </joint>
  <link name="link6">
    <visual>
      <geometry>
        <cylinder length="0.04" radius="0.025"/>
      </geometry>
      <origin rpy="0 0 0" xyz="0 0 0.02"/>
      <material name="white"/>
    </visual>
    <inertial>
      <mass value="1.0"/>
      <inertia ixx="0.1" ixy="0.0" ixz="0.0" iyy="0.1" iyz="0.0" izz="0.1"/>
    </inertial>
    <collision>
      <geometry>
        <cylinder length="0.04" radius="0.025"/>
      </geometry>
    </collision>
  </link>
  <joint name="link5_link6" type="revolute">
    <axis xyz="0 0 1"/>
    <limit effort="100.0" lower="-3.1416" upper="3.1416" velocity="0.5"/>
    <parent link="link5"/>
    <child link="link6"/>
    <origin rpy="0 0 0" xyz="0.05 0 0.45"/>
  </joint>
  <link name="link7">
    <visual>
      <geometry>
        <cylinder length="0.02" radius="0.02"/>
      </geometry>
      <origin rpy="0 1.57 0" xyz="0.01 0 0"/>
      <material name="black"/>
    </visual>
    <inertial>
      <mass value="1.0"/>
      <inertia ixx="0.1" ixy="0.0" ixz="0.0" iyy="0.1" iyz="0.0" izz="0.1"/>
    </inertial>
    <collision>
      <geometry>
        <cylinder length="0.02" radius="0.02"/>
      </geometry>
    </collision>
  </link>
  <joint name="link6_link7" type="fixed">
    <parent link="link6"/>
    <child link="link7"/>
    <origin rpy="0 0 0" xyz="0.025 0 0.02"/>
  </joint>
  <link name="link8">
    <visual>
      <geometry>
        <box size="0.03 0.03 0.04"/>
      </geometry>
      <origin rpy="0 0 0" xyz="0 0 0.02"/>
      <material name="white"/>
    </visual>
    <inertial>
      <mass value="1.0"/>
      <inertia ixx="0.1" ixy="0.0" ixz="0.0" iyy="0.1" iyz="0.0" izz="0.1"/>
    </inertial>
    <collision>
      <geometry>
        <box size="0.03 0.03 0.04"/>
      </geometry>
    </collision>
  </link>
  <joint name="link7_link8" type="revolute">
    <axis xyz="1 0 0"/>
    <limit effort="100.0" lower="-1.57" upper="1.57" velocity="0.5"/>
    <parent link="link7"/>
    <child link="link8"/>
    <origin rpy="0 0 0" xyz="0.01 0 0.02"/>
  </joint>
  <link name="link9">
    <visual>
      <geometry>
        <box size="0.04 0.04 0.02"/>
      </geometry>
      <origin rpy="0 0 0" xyz="0 0 0.01"/>
      <material name="white"/>
    </visual>
    <inertial>
      <mass value="0.5"/>
      <inertia ixx="0.1" ixy="0.0" ixz="0.0" iyy="0.1" iyz="0.0" izz="0.1"/>
    </inertial>
    <collision>
      <geometry>
        <box size="0.04 0.04 0.02"/>
      </geometry>
    </collision>
  </link>
  <joint name="link8_link9" type="fixed">
    <parent link="link8"/>
    <child link="link9"/>
    <origin rpy="0 0 0" xyz="0 0 0.02"/>
  </joint>
  <link name="link10">
    <visual>
      <geometry>
        <box size="0.08 0.01 0.02"/>
      </geometry>
      <origin rpy="0 1.57 0" xyz="0 0 0.04"/>
      <material name="blue"/>
    </visual>
    <inertial>
      <mass value="0.2"/>
      <inertia ixx="0.1" ixy="0.0" ixz="0.0" iyy="0.1" iyz="0.0" izz="0.1"/>
    </inertial>
    <collision>
      <geometry>
        <box size="0.08 0.01 0.02"/>
      </geometry>
    </collision>
  </link>
  <joint name="link9_link10" type="revolute">
    <axis xyz="1 0 0"/>
    <limit effort="100.0" lower="0.25" upper="1.18" velocity="0.5"/>
    <parent link="link9"/>
    <child link="link10"/>
    <origin rpy="-1 0 0" xyz="0 0.02 0.01"/>
  </joint>
  <link name="link11">
    <visual>
      <geometry>
        <box size="0.08 0.01 0.02"/>
      </geometry>
      <origin rpy="0 1.57 0" xyz="0 0 0.04"/>
      <material name="blue"/>
    </visual>
    <inertial>
      <mass value="0.2"/>
      <inertia ixx="0.1" ixy="0.0" ixz="0.0" iyy="0.1" iyz="0.0" izz="0.1"/>
    </inertial>
    <collision>
      <geometry>
        <box size="0.08 0.01 0.02"/>
      </geometry>
    </collision>
  </link>
  <joint name="link9_link11" type="revolute">
    <axis xyz="1 0 0"/>
    <limit effort="100.0" lower="-1.18" upper="-0.25" velocity="0.5"/>
    <parent link="link9"/>
    <child link="link11"/>
    <origin rpy="1 0 0" xyz="0 -0.02 0.01"/>
  </joint>
</robot>

